Workbook

Sheet README
A1: Brisbane tree maintenance register
A2: Built 2026-10-28 by build_workbook.py from Brisbane City Council open data.
A4: How the sheets link
A5: Tree_Register: one row per tree, keyed by Tree_ID (e.g. SHW-0661). Columns A–N are Council data; green columns O–V are formulas that summarise that tree's rows in the two log sheets.
A6: Health_Assessments: one row per inspection. Enter the Tree_ID; pick Condition, Issue_Type, Risk_Rating and Recommended_Outcome from the dropdowns.
A7: Maintenance_Log: one row per job. Enter the Tree_ID (and Assessment_ID if the job came from an inspection). Required_Clearance_m fills in from Clearance_Context.
A8: Protected_Areas: every Natural Assets Local Law protected-vegetation polygon and Significant landscape tree overlay site, with its centroid. Register column M lists the protected areas each tree falls in.
A9: Lookups: dropdown values. Outcomes, request reasons and clearances come from Council's pages; the condition and risk scales are placeholders (see the cell comments).
A11: What to edit
A12: Yellow cells in Health_Assessments and Maintenance_Log are for your entries (any row down to 5001 works; only the first 50 are shaded). Green cells are formulas: don't type over them.
A13: Grey italic row 2 in each log is an example showing the format. Replace or delete it.
A14: To add trees you survey yourself, add rows to Tree_Register with your own Tree_ID prefix and copy the green formulas down.
... A22: Re-run: python3 build_workbook.py brisbane_tree_maintenance.xlsx. This replaces the whole file, including both logs, so copy your log rows out first and paste them back afterwards.

Sheet Tree_Register
A1: Tree_ID | B1: Source | C1: Source_Tree_ID | D1: Latitude | E1: Longitude | F1: Scientific_Name | G1: Common_Name | H1: Family | I1: Height_m | J1: Crown_Width_m | K1: DBH_mm | L1: Year_Established | M1: Protected_Vegetation_Areas | N1: In_Significant_Landscape_Tree_Overlay | O1: Assessments | P1: Last_Assessed | Q1: Latest_Condition | R1: Latest_Risk | S1: Latest_Recommended_Outcome | T1: Maintenance_Jobs | U1: Last_Maintenance | V1: Open_Jobs
A2: SHW-0001 | B2: Sherwood Arboretum | C2: 1 | D2: -27.529198 | E2: 152.97359 | F2: Agathis robusta | G2: Queensland kauri pine | H2: Araucariaceae | I2: 26 | J2: 20 | K2: 890 | L2: 1925 | M2: NALL-CV-2257, NALL-SNV-881, NALL-WWV-2529 | N2: No | O2: =COUNTIF(Health_Assessments!$B$2:$B$5001,A2) -> 0 | P2: =IF(O2=0,"",_xlfn.MAXIFS(Health_Assessments!$C$2:$C$5001,Health_Assessments!$B$2:$B$5001,A2)) | Q2: =IF(O2=0,"",LOOKUP(2,1/((Health_Assessments!$B$2:$B$5001=A2)*(Health_Assessments!$C$2:$C$5001=P2)),Health_Assessments!$E$2:$E$5001)) | R2: =IF(O2=0,"",LOOKUP(2,1/((Health_Assessments!$B$2:$B$5001=A2)*(Health_Assessments!$C$2:$C$5001=P2)),Health_Assessments!$G$2:$G$5001)) | S2: =IF(O2=0,"",LOOKUP(2,1/((Health_Assessments!$B$2:$B$5001=A2)*(Health_Assessments!$C$2:$C$5001=P2)),Health_Assessments!$H$2:$H$5001)) | T2: =COUNTIF(Maintenance_Log!$B$2:$B$5001,A2) -> 0 | U2: =IF(T2=0,"",_xlfn.MAXIFS(Maintenance_Log!$D$2:$D$5001,Maintenance_Log!$B$2:$B$5001,A2)) | V2: =COUNTIFS(Maintenance_Log!$B$2:$B$5001,A2,Maintenance_Log!$H$2:$H$5001,"<>Completed",Maintenance_Log!$H$2:$H$5001,"<>Cancelled") -> 0
A3: SHW-0002 | B3: Sherwood Arboretum | C3: 2 | D3: -27.529221 | E3: 152.97346 | F3: Agathis robusta | G3: Queensland kauri pine | H3: Araucariaceae | I3: 26 | J3: 14 | K3: 780 | L3: 1925 | M3: NALL-CV-2257, NALL-SNV-881, NALL-WWV-2529 | N3: No | O3: =COUNTIF(Health_Assessments!$B$2:$B$5001,A3) -> 0 | P3: =IF(O3=0,"",_xlfn.MAXIFS(Health_Assessments!$C$2:$C$5001,Health_Assessments!$B$2:$B$5001,A3)) | Q3: =IF(O3=0,"",LOOKUP(2,1/((Health_Assessments!$B$2:$B$5001=A3)*(Health_Assessments!$C$2:$C$5001=P3)),Health_Assessments!$E$2:$E$5001)) | R3: =IF(O3=0,"",LOOKUP(2,1/((Health_Assessments!$B$2:$B$5001=A3)*(Health_Assessments!$C$2:$C$5001=P3)),Health_Assessments!$G$2:$G$5001)) | S3: =IF(O3=0,"",LOOKUP(2,1/((Health_Assessments!$B$2:$B$5001=A3)*(Health_Assessments!$C$2:$C$5001=P3)),Health_Assessments!$H$2:$H$5001)) | T3: =COUNTIF(Maintenance_Log!$B$2:$B$5001,A3) -> 0 | U3: =IF(T3=0,"",_xlfn.MAXIFS(Maintenance_Log!$D$2:$D$5001,Maintenance_Log!$B$2:$B$5001,A3)) | V3: =COUNTIFS(Maintenance_Log!$B$2:$B$5001,A3,Maintenance_Log!$H$2:$H$5001,"<>Completed",Maintenance_Log!$H$2:$H$5001,"<>Cancelled") -> 0
A4: SHW-0003 | B4: Sherwood Arboretum | C4: 3 | D4: -27.529305 | E4: 152.9736 | F4: Agathis robusta | G4: Queensland kauri pine | H4: Araucariaceae | I4: 27 | J4: 11 | K4: 570 | L4: 1925 | M4: NALL-CV-2257, NALL-SNV-881, NALL-WWV-2529 | N4: No | O4: =COUNTIF(Health_Assessments!$B$2:$B$5001,A4) -> 0 | P4: =IF(O4=0,"",_xlfn.MAXIFS(Health_Assessments!$C$2:$C$5001,Health_Assessments!$B$2:$B$5001,A4)) | Q4: =IF(O4=0,"",LOOKUP(2,1/((Health_Assessments!$B$2:$B$5001=A4)*(Health_Assessments!$C$2:$C$5001=P4)),Health_Assessments!$E$2:$E$5001)) | R4: =IF(O4=0,"",LOOKUP(2,1/((Health_Assessments!$B$2:$B$5001=A4)*(Health_Assessments!$C$2:$C$5001=P4)),Health_Assessments!$G$2:$G$5001)) | S4: =IF(O4=0,"",LOOKUP(2,1/((Health_Assessments!$B$2:$B$5001=A4)*(Health_Assessments!$C$2:$C$5001=P4)),Health_Assessments!$H$2:$H$5001)) | T4: =COUNTIF(Maintenance_Log!$B$2:$B$5001,A4) -> 0 | U4: =IF(T4=0,"",_xlfn.MAXIFS(Maintenance_Log!$D$2:$D$5001,Maintenance_Log!$B$2:$B$5001,A4)) | V4: =COUNTIFS(Maintenance_Log!$B$2:$B$5001,A4,Maintenance_Log!$H$2:$H$5001,"<>Completed",Maintenance_Log!$H$2:$H$5001,"<>Cancelled") -> 0
A5: SHW-0004 | B5: Sherwood Arboretum | C5: 4 | D5: -27.529327 | E5: 152.97349 | F5: Agathis robusta | G5: Queensland kauri pine | H5: Araucariaceae | I5: 25 | J5: 15 | K5: 800 | L5: 1925 | M5: NALL-CV-2257, NALL-SNV-881, NALL-WWV-2529 | N5: No | O5: =COUNTIF(Health_Assessments!$B$2:$B$5001,A5) -> 0 | P5: =IF(O5=0,"",_xlfn.MAXIFS(Health_Assessments!$C$2:$C$5001,Health_Assessments!$B$2:$B$5001,A5)) | Q5: =IF(O5=0,"",LOOKUP(2,1/((Health_Assessments!$B$2:$B$5001=A5)*(Health_Assessments!$C$2:$C$5001=P5)),Health_Assessments!$E$2:$E$5001)) | R5: =IF(O5=0,"",LOOKUP(2,1/((Health_Assessments!$B$2:$B$5001=A5)*(Health_Assessments!$C$2:$C$5001=P5)),Health_Assessments!$G$2:$G$5001)) | S5: =IF(O5=0,"",LOOKUP(2,1/((Health_Assessments!$B$2:$B$5001=A5)*(Health_Assessments!$C$2:$C$5001=P5)),Health_Assessments!$H$2:$H$5001)) | T5: =COUNTIF(Maintenance_Log!$B$2:$B$5001,A5) -> 0 | U5: =IF(T5=0,"",_xlfn.MAXIFS(Maintenance_Log!$D$2:$D$5001,Maintenance_Log!$B$2:$B$5001,A5)) | V5: =COUNTIFS(Maintenance_Log!$B$2:$B$5001,A5,Maintenance_Log!$H$2:$H$5001,"<>Completed",Maintenance_Log!$H$2:$H$5001,"<>Cancelled") -> 0
A6: SHW-0005 | B6: Sherwood Arboretum | C6: 5 | D6: -27.529409 | E6: 152.97362 | F6: Agathis robusta | G6: Queensland kauri pine | H6: Araucariaceae | I6: 20 | J6: 16 | K6: 620 | L6: 1925 | M6: NALL-CV-2257, NALL-SNV-881 | N6: No | O6: =COUNTIF(Health_Assessments!$B$2:$B$5001,A6) -> 0 | P6: =IF(O6=0,"",_xlfn.MAXIFS(Health_Assessments!$C$2:$C$5001,Health_Assessments!$B$2:$B$5001,A6)) | Q6: =IF(O6=0,"",LOOKUP(2,1/((Health_Assessments!$B$2:$B$5001=A6)*(Health_Assessments!$C$2:$C$5001=P6)),Health_Assessments!$E$2:$E$5001)) | R6: =IF(O6=0,"",LOOKUP(2,1/((Health_Assessments!$B$2:$B$5001=A6)*(Health_Assessments!$C$2:$C$5001=P6)),Health_Assessments!$G$2:$G$5001)) | S6: =IF(O6=0,"",LOOKUP(2,1/((Health_Assessments!$B$2:$B$5001=A6)*(Health_Assessments!$C$2:$C$5001=P6)),Health_Assessments!$H$2:$H$5001)) | T6: =COUNTIF(Maintenance_Log!$B$2:$B$5001,A6) -> 0 | U6: =IF(T6=0,"",_xlfn.MAXIFS(Maintenance_Log!$D$2:$D$5001,Maintenance_Log!$B$2:$B$5001,A6)) | V6: =COUNTIFS(Maintenance_Log!$B$2:$B$5001,A6,Maintenance_Log!$H$2:$H$5001,"<>Completed",Maintenance_Log!$H$2:$H$5001,"<>Cancelled") -> 0
A7: SHW-0006 | B7: Sherwood Arboretum | C7: 6 | D7: -27.529433 | E7: 152.97351 | F7: Agathis robusta | G7: Queensland kauri pine | H7: Araucariaceae | I7: 22 | J7: 15 | K7: 370 | L7: 1925 | M7: NALL-CV-2257, NALL-SNV-881, NALL-WWV-2529 | N7: No | O7: =COUNTIF(Health_Assessments!$B$2:$B$5001,A7) -> 0 | P7: =IF(O7=0,"",_xlfn.MAXIFS(Health_Assessments!$C$2:$C$5001,Health_Assessments!$B$2:$B$5001,A7)) | Q7: =IF(O7=0,"",LOOKUP(2,1/((Health_Assessments!$B$2:$B$5001=A7)*(Health_Assessments!$C$2:$C$5001=P7)),Health_Assessments!$E$2:$E$5001)) | R7: =IF(O7=0,"",LOOKUP(2,1/((Health_Assessments!$B$2:$B$5001=A7)*(Health_Assessments!$C$2:$C$5001=P7)),Health_Assessments!$G$2:$G$5001)) | S7: =IF(O7=0,"",LOOKUP(2,1/((Health_Assessments!$B$2:$B$5001=A7)*(Health_Assessments!$C$2:$C$5001=P7)),Health_Assessments!$H$2:$H$5001)) | T7: =COUNTIF(Maintenance_Log!$B$2:$B$5001,A7) -> 0 | U7: =IF(T7=0,"",_xlfn.MAXIFS(Maintenance_Log!$D$2:$D$5001,Maintenance_Log!$B$2:$B$5001,A7)) | V7: =COUNTIFS(Maintenance_Log!$B$2:$B$5001,A7,Maintenance_Log!$H$2:$H$5001,"<>Completed",Maintenance_Log!$H$2:$H$5001,"<>Cancelled") -> 0
A8: SHW-0007 | B8: Sherwood Arboretum | C8: 7 | D8: -27.529505 | E8: 152.97366 | F8: Agathis robusta | G8: Queensland kauri pine | H8: Araucariaceae | I8: 21 | J8: 10 | K8: 650 | L8: 1925 | M8: NALL-CV-2257, NALL-SNV-881 | N8: No | O8: =COUNTIF(Health_Assessments!$B$2:$B$5001,A8) -> 0 | P8: =IF(O8=0,"",_xlfn.MAXIFS(Health_Assessments!$C$2:$C$5001,Health_Assessments!$B$2:$B$5001,A8)) | Q8: =IF(O8=0,"",LOOKUP(2,1/((Health_Assessments!$B$2:$B$5001=A8)*(Health_Assessments!$C$2:$C$5001=P8)),Health_Assessments!$E$2:$E$5001)) | R8: =IF(O8=0,"",LOOKUP(2,1/((Health_Assessments!$B$2:$B$5001=A8)*(Health_Assessments!$C$2:$C$5001=P8)),Health_Assessments!$G$2:$G$5001)) | S8: =IF(O8=0,"",LOOKUP(2,1/((Health_Assessments!$B$2:$B$5001=A8)*(Health_Assessments!$C$2:$C$5001=P8)),Health_Assessments!$H$2:$H$5001)) | T8: =COUNTIF(Maintenance_Log!$B$2:$B$5001,A8) -> 0 | U8: =IF(T8=0,"",_xlfn.MAXIFS(Maintenance_Log!$D$2:$D$5001,Maintenance_Log!$B$2:$B$5001,A8)) | V8: =COUNTIFS(Maintenance_Log!$B$2:$B$5001,A8,Maintenance_Log!$H$2:$H$5001,"<>Completed",Maintenance_Log!$H$2:$H$5001,"<>Cancelled") -> 0
A9: SHW-0008 | B9: Sherwood Arboretum | C9: 8 | D9: -27.529542 | E9: 152.97354 | F9: Agathis robusta | G9: Queensland kauri pine | H9: Araucariaceae | I9: 23 | J9: 10 | K9: 540 | L9: 1925 | M9: NALL-CV-2257, NALL-SNV-881, NALL-WWV-2529 | N9: No | O9: =COUNTIF(Health_Assessments!$B$2:$B$5001,A9) -> 0 | P9: =IF(O9=0,"",_xlfn.MAXIFS(Health_Assessments!$C$2:$C$5001,Health_Assessments!$B$2:$B$5001,A9)) | Q9: =IF(O9=0,"",LOOKUP(2,1/((Health_Assessments!$B$2:$B$5001=A9)*(Health_Assessments!$C$2:$C$5001=P9)),Health_Assessments!$E$2:$E$5001)) | R9: =IF(O9=0,"",LOOKUP(2,1/((Health_Assessments!$B$2:$B$5001=A9)*(Health_Assessments!$C$2:$C$5001=P9)),Health_Assessments!$G$2:$G$5001)) | S9: =IF(O9=0,"",LOOKUP(2,1/((Health_Assessments!$B$2:$B$5001=A9)*(Health_Assessments!$C$2:$C$5001=P9)),Health_Assessments!$H$2:$H$5001)) | T9: =COUNTIF(Maintenance_Log!$B$2:$B$5001,A9) -> 0 | U9: =IF(T9=0,"",_xlfn.MAXIFS(Maintenance_Log!$D$2:$D$5001,Maintenance_Log!$B$2:$B$5001,A9)) | V9: =COUNTIFS(Maintenance_Log!$B$2:$B$5001,A9,Maintenance_Log!$H$2:$H$5001,"<>Completed",Maintenance_Log!$H$2:$H$5001,"<>Cancelled") -> 0
A10: SHW-0009 | B10: Sherwood Arboretum | C10: 9 | D10: -27.529633 | E10: 152.97367 | F10: Agathis robusta | G10: Queensland kauri pine | H10: Araucariaceae | I10: 24 | J10: 16 | K10: 670 | L10: 1925 | M10: NALL-CV-2257, NALL-SNV-881 | N10: No | O10: =COUNTIF(Health_Assessments!$B$2:$B$5001,A10) -> 0 | P10: =IF(O10=0,"",_xlfn.MAXIFS(Health_Assessments!$C$2:$C$5001,Health_Assessments!$B$2:$B$5001,A10)) | Q10: =IF(O10=0,"",LOOKUP(2,1/((Health_Assessments!$B$2:$B$5001=A10)*(Health_Assessments!$C$2:$C$5001=P10)),Health_Assessments!$E$2:$E$5001)) | R10: =IF(O10=0,"",LOOKUP(2,1/((Health_Assessments!$B$2:$B$5001=A10)*(Health_Assessments!$C$2:$C$5001=P10)),Health_Assessments!$G$2:$G$5001)) | S10: =IF(O10=0,"",LOOKUP(2,1/((Health_Assessments!$B$2:$B$5001=A10)*(Health_Assessments!$C$2:$C$5001=P10)),Health_Assessments!$H$2:$H$5001)) | T10: =COUNTIF(Maintenance_Log!$B$2:$B$5001,A10) -> 0 | U10: =IF(T10=0,"",_xlfn.MAXIFS(Maintenance_Log!$D$2:$D$5001,Maintenance_Log!$B$2:$B$5001,A10)) | V10: =COUNTIFS(Maintenance_Log!$B$2:$B$5001,A10,Maintenance_Log!$H$2:$H$5001,"<>Completed",Maintenance_Log!$H$2:$H$5001,"<>Cancelled") -> 0
A11: SHW-0010 | B11: Sherwood Arboretum | C11: 10 | D11: -27.52965 | E11: 152.97355 | F11: Agathis robusta | G11: Queensland kauri pine | H11: Araucariaceae | I11: 24 | J11: 13 | K11: 570 | L11: 1925 | M11: NALL-CV-2257, NALL-SNV-881 | N11: No | O11: =COUNTIF(Health_Assessments!$B$2:$B$5001,A11) -> 0 | P11: =IF(O11=0,"",_xlfn.MAXIFS(Health_Assessments!$C$2:$C$5001,Health_Assessments!$B$2:$B$5001,A11)) | Q11: =IF(O11=0,"",LOOKUP(2,1/((Health_Assessments!$B$2:$B$5001=A11)*(Health_Assessments!$C$2:$C$5001=P11)),Health_Assessments!$E$2:$E$5001)) | R11: =IF(O11=0,"",LOOKUP(2,1/((Health_Assessments!$B$2:$B$5001=A11)*(Health_Assessments!$C$2:$C$5001=P11)),Health_Assessments!$G$2:$G$5001)) | S11: =IF(O11=0,"",LOOKUP(2,1/((Health_Assessments!$B$2:$B$5001=A11)*(Health_Assessments!$C$2:$C$5001=P11)),Health_Assessments!$H$2:$H$5001)) | T11: =COUNTIF(Maintenance_Log!$B$2:$B$5001,A11) -> 0 | U11: =IF(T11=0,"",_xlfn.MAXIFS(Maintenance_Log!$D$2:$D$5001,Maintenance_Log!$B$2:$B$5001,A11)) | V11: =COUNTIFS(Maintenance_Log!$B$2:$B$5001,A11,Maintenance_Log!$H$2:$H$5001,"<>Completed",Maintenance_Log!$H$2:$H$5001,"<>Cancelled") -> 0
A12: SHW-0011 | B12: Sherwood Arboretum | C12: 11 | D12: -27.529735 | E12: 152.97369 | F12: Agathis robusta | G12: Queensland kauri pine | H12: Araucariaceae | I12: 25 | J12: 15 | K12: 680 | L12: 1925 | M12: NALL-CV-2257, NALL-SNV-881 | N12: No | O12: =COUNTIF(Health_Assessments!$B$2:$B$5001,A12) -> 0 | P12: =IF(O12=0,"",_xlfn.MAXIFS(Health_Assessments!$C$2:$C$5001,Health_Assessments!$B$2:$B$5001,A12)) | Q12: =IF(O12=0,"",LOOKUP(2,1/((Health_Assessments!$B$2:$B$5001=A12)*(Health_Assessments!$C$2:$C$5001=P12)),Health_Assessments!$E$2:$E$5001)) | R12: =IF(O12=0,"",LOOKUP(2,1/((Health_Assessments!$B$2:$B$5001=A12)*(Health_Assessments!$C$2:$C$5001=P12)),Health_Assessments!$G$2:$G$5001)) | S12: =IF(O12=0,"",LOOKUP(2,1/((Health_Assessments!$B$2:$B$5001=A12)*(Health_Assessments!$C$2:$C$5001=P12)),Health_Assessments!$H$2:$H$5001)) | T12: =COUNTIF(Maintenance_Log!$B$2:$B$5001,A12) -> 0 | U12: =IF(T12=0,"",_xlfn.MAXIFS(Maintenance_Log!$D$2:$D$5001,Maintenance_Log!$B$2:$B$5001,A12)) | V12: =COUNTIFS(Maintenance_Log!$B$2:$B$5001,A12,Maintenance_Log!$H$2:$H$5001,"<>Completed",Maintenance_Log!$H$2:$H$5001,"<>Cancelled") -> 0
A13: SHW-0012 | B13: Sherwood Arboretum | C13: 12 | D13: -27.529762 | E13: 152.97357 | F13: Agathis robusta | G13: Queensland kauri pine | H13: Araucariaceae | I13: 22 | J13: 15 | K13: 770 | L13: 1925 | M13: NALL-CV-2257, NALL-SNV-881 | N13: No | O13: =COUNTIF(Health_Assessments!$B$2:$B$5001,A13) -> 0 | P13: =IF(O13=0,"",_xlfn.MAXIFS(Health_Assessments!$C$2:$C$5001,Health_Assessments!$B$2:$B$5001,A13)) | Q13: =IF(O13=0,"",LOOKUP(2,1/((Health_Assessments!$B$2:$B$5001=A13)*(Health_Assessments!$C$2:$C$5001=P13)),Health_Assessments!$E$2:$E$5001)) | R13: =IF(O13=0,"",LOOKUP(2,1/((Health_Assessments!$B$2:$B$5001=A13)*(Health_Assessments!$C$2:$C$5001=P13)),Health_Assessments!$G$2:$G$5001)) | S13: =IF(O13=0,"",LOOKUP(2,1/((Health_Assessments!$B$2:$B$5001=A13)*(Health_Assessments!$C$2:$C$5001=P13)),Health_Assessments!$H$2:$H$5001)) | T13: =COUNTIF(Maintenance_Log!$B$2:$B$5001,A13) -> 0 | U13: =IF(T13=0,"",_xlfn.MAXIFS(Maintenance_Log!$D$2:$D$5001,Maintenance_Log!$B$2:$B$5001,A13)) | V13: =COUNTIFS(Maintenance_Log!$B$2:$B$5001,A13,Maintenance_Log!$H$2:$H$5001,"<>Completed",Maintenance_Log!$H$2:$H$5001,"<>Cancelled") -> 0
... A41: SHW-0040 | B41: Sherwood Arboretum | C41: 40 | D41: -27.531285 | E41: 152.97385 | F41: Agathis robusta | G41: Queensland kauri pine | H41: Araucariaceae | I41: 18 | J41: 12 | K41: 640 | L41: 1925 | M41: NALL-CV-2257, NALL-SNV-881, NALL-WWV-2529 | N41: No | O41: =COUNTIF(Health_Assessments!$B$2:$B$5001,A41) -> 0 | P41: =IF(O41=0,"",_xlfn.MAXIFS(Health_Assessments!$C$2:$C$5001,Health_Assessments!$B$2:$B$5001,A41)) | Q41: =IF(O41=0,"",LOOKUP(2,1/((Health_Assessments!$B$2:$B$5001=A41)*(Health_Assessments!$C$2:$C$5001=P41)),Health_Assessments!$E$2:$E$5001)) | R41: =IF(O41=0,"",LOOKUP(2,1/((Health_Assessments!$B$2:$B$5001=A41)*(Health_Assessments!$C$2:$C$5001=P41)),Health_Assessments!$G$2:$G$5001)) | S41: =IF(O41=0,"",LOOKUP(2,1/((Health_Assessments!$B$2:$B$5001=A41)*(Health_Assessments!$C$2:$C$5001=P41)),Health_Assessments!$H$2:$H$5001)) | T41: =COUNTIF(Maintenance_Log!$B$2:$B$5001,A41) -> 0 | U41: =IF(T41=0,"",_xlfn.MAXIFS(Maintenance_Log!$D$2:$D$5001,Maintenance_Log!$B$2:$B$5001,A41)) | V41: =COUNTIFS(Maintenance_Log!$B$2:$B$5001,A41,Maintenance_Log!$H$2:$H$5001,"<>Completed",Maintenance_Log!$H$2:$H$5001,"<>Cancelled") -> 0
A42: SHW-0041 | B42: Sherwood Arboretum | C42: 41 | D42: -27.531356 | E42: 152.974 | F42: Agathis robusta | G42: Queensland kauri pine | H42: Araucariaceae | I42: 17 | J42: 11 | K42: 770 | M42: NALL-CV-2257, NALL-SNV-881, NALL-WWV-2529 | N42: No | O42: =COUNTIF(Health_Assessments!$B$2:$B$5001,A42) -> 0 | P42: =IF(O42=0,"",_xlfn.MAXIFS(Health_Assessments!$C$2:$C$5001,Health_Assessments!$B$2:$B$5001,A42)) | Q42: =IF(O42=0,"",LOOKUP(2,1/((Health_Assessments!$B$2:$B$5001=A42)*(Health_Assessments!$C$2:$C$5001=P42)),Health_Assessments!$E$2:$E$5001)) | R42: =IF(O42=0,"",LOOKUP(2,1/((Health_Assessments!$B$2:$B$5001=A42)*(Health_Assessments!$C$2:$C$5001=P42)),Health_Assessments!$G$2:$G$5001)) | S42: =IF(O42=0,"",LOOKUP(2,1/((Health_Assessments!$B$2:$B$5001=A42)*(Health_Assessments!$C$2:$C$5001=P42)),Health_Assessments!$H$2:$H$5001)) | T42: =COUNTIF(Maintenance_Log!$B$2:$B$5001,A42) -> 0 | U42: =IF(T42=0,"",_xlfn.MAXIFS(Maintenance_Log!$D$2:$D$5001,Maintenance_Log!$B$2:$B$5001,A42)) | V42: =COUNTIFS(Maintenance_Log!$B$2:$B$5001,A42,Maintenance_Log!$H$2:$H$5001,"<>Completed",Maintenance_Log!$H$2:$H$5001,"<>Cancelled") -> 0
A43: SHW-0042 | B43: Sherwood Arboretum | C43: 42 | D43: -27.531385 | E43: 152.97387 | F43: Agathis robusta | G43: Queensland kauri pine | H43: Araucariaceae | I43: 20 | J43: 15 | K43: 650 | L43: 1925 | M43: NALL-CV-2257, NALL-SNV-881, NALL-WWV-2529 | N43: No | O43: =COUNTIF(Health_Assessments!$B$2:$B$5001,A43) -> 0 | P43: =IF(O43=0,"",_xlfn.MAXIFS(Health_Assessments!$C$2:$C$5001,Health_Assessments!$B$2:$B$5001,A43)) | Q43: =IF(O43=0,"",LOOKUP(2,1/((Health_Assessments!$B$2:$B$5001=A43)*(Health_Assessments!$C$2:$C$5001=P43)),Health_Assessments!$E$2:$E$5001)) | R43: =IF(O43=0,"",LOOKUP(2,1/((Health_Assessments!$B$2:$B$5001=A43)*(Health_Assessments!$C$2:$C$5001=P43)),Health_Assessments!$G$2:$G$5001)) | S43: =IF(O43=0,"",LOOKUP(2,1/((Health_Assessments!$B$2:$B$5001=A43)*(Health_Assessments!$C$2:$C$5001=P43)),Health_Assessments!$H$2:$H$5001)) | T43: =COUNTIF(Maintenance_Log!$B$2:$B$5001,A43) -> 0 | U43: =IF(T43=0,"",_xlfn.MAXIFS(Maintenance_Log!$D$2:$D$5001,Maintenance_Log!$B$2:$B$5001,A43)) | V43: =COUNTIFS(Maintenance_Log!$B$2:$B$5001,A43,Maintenance_Log!$H$2:$H$5001,"<>Completed",Maintenance_Log!$H$2:$H$5001,"<>Cancelled") -> 0
A44: SHW-0043 | B44: Sherwood Arboretum | C44: 43 | D44: -27.531474 | E44: 152.97401 | F44: Agathis robusta | G44: Queensland kauri pine | H44: Araucariaceae | I44: 8 | J44: 4 | K44: 140 | L44: 2014 | M44: NALL-CV-2257, NALL-SNV-881, NALL-WWV-2529 | N44: No | O44: =COUNTIF(Health_Assessments!$B$2:$B$5001,A44) -> 0 | P44: =IF(O44=0,"",_xlfn.MAXIFS(Health_Assessments!$C$2:$C$5001,Health_Assessments!$B$2:$B$5001,A44)) | Q44: =IF(O44=0,"",LOOKUP(2,1/((Health_Assessments!$B$2:$B$5001=A44)*(Health_Assessments!$C$2:$C$5001=P44)),Health_Assessments!$E$2:$E$5001)) | R44: =IF(O44=0,"",LOOKUP(2,1/((Health_Assessments!$B$2:$B$5001=A44)*(Health_Assessments!$C$2:$C$5001=P44)),Health_Assessments!$G$2:$G$5001)) | S44: =IF(O44=0,"",LOOKUP(2,1/((Health_Assessments!$B$2:$B$5001=A44)*(Health_Assessments!$C$2:$C$5001=P44)),Health_Assessments!$H$2:$H$5001)) | T44: =COUNTIF(Maintenance_Log!$B$2:$B$5001,A44) -> 0 | U44: =IF(T44=0,"",_xlfn.MAXIFS(Maintenance_Log!$D$2:$D$5001,Maintenance_Log!$B$2:$B$5001,A44)) | V44: =COUNTIFS(Maintenance_Log!$B$2:$B$5001,A44,Maintenance_Log!$H$2:$H$5001,"<>Completed",Maintenance_Log!$H$2:$H$5001,"<>Cancelled") -> 0
A45: SHW-0044 | B45: Sherwood Arboretum | C45: 44 | D45: -27.531486 | E45: 152.9739 | F45: Agathis robusta | G45: Queensland kauri pine | H45: Araucariaceae | I45: 10 | J45: 4 | K45: 290 | L45: 1925 | M45: NALL-CV-2257, NALL-SNV-881, NALL-WWV-2529 | N45: No | O45: =COUNTIF(Health_Assessments!$B$2:$B$5001,A45) -> 0 | P45: =IF(O45=0,"",_xlfn.MAXIFS(Health_Assessments!$C$2:$C$5001,Health_Assessments!$B$2:$B$5001,A45)) | Q45: =IF(O45=0,"",LOOKUP(2,1/((Health_Assessments!$B$2:$B$5001=A45)*(Health_Assessments!$C$2:$C$5001=P45)),Health_Assessments!$E$2:$E$5001)) | R45: =IF(O45=0,"",LOOKUP(2,1/((Health_Assessments!$B$2:$B$5001=A45)*(Health_Assessments!$C$2:$C$5001=P45)),Health_Assessments!$G$2:$G$5001)) | S45: =IF(O45=0,"",LOOKUP(2,1/((Health_Assessments!$B$2:$B$5001=A45)*(Health_Assessments!$C$2:$C$5001=P45)),Health_Assessments!$H$2:$H$5001)) | T45: =COUNTIF(Maintenance_Log!$B$2:$B$5001,A45) -> 0 | U45: =IF(T45=0,"",_xlfn.MAXIFS(Maintenance_Log!$D$2:$D$5001,Maintenance_Log!$B$2:$B$5001,A45)) | V45: =COUNTIFS(Maintenance_Log!$B$2:$B$5001,A45,Maintenance_Log!$H$2:$H$5001,"<>Completed",Maintenance_Log!$H$2:$H$5001,"<>Cancelled") -> 0
A46: SHW-0045 | B46: Sherwood Arboretum | C46: 45 | D46: -27.531583 | E46: 152.97403 | F46: Agathis robusta | G46: Queensland kauri pine | H46: Araucariaceae | I46: 9 | J46: 2 | K46: 170 | L46: 2014 | M46: NALL-CV-2257, NALL-SNV-881, NALL-WWV-2529 | N46: No | O46: =COUNTIF(Health_Assessments!$B$2:$B$5001,A46) -> 0 | P46: =IF(O46=0,"",_xlfn.MAXIFS(Health_Assessments!$C$2:$C$5001,Health_Assessments!$B$2:$B$5001,A46)) | Q46: =IF(O46=0,"",LOOKUP(2,1/((Health_Assessments!$B$2:$B$5001=A46)*(Health_Assessments!$C$2:$C$5001=P46)),Health_Assessments!$E$2:$E$5001)) | R46: =IF(O46=0,"",LOOKUP(2,1/((Health_Assessments!$B$2:$B$5001=A46)*(Health_Assessments!$C$2:$C$5001=P46)),Health_Assessments!$G$2:$G$5001)) | S46: =IF(O46=0,"",LOOKUP(2,1/((Health_Assessments!$B$2:$B$5001=A46)*(Health_Assessments!$C$2:$C$5001=P46)),Health_Assessments!$H$2:$H$5001)) | T46: =COUNTIF(Maintenance_Log!$B$2:$B$5001,A46) -> 0 | U46: =IF(T46=0,"",_xlfn.MAXIFS(Maintenance_Log!$D$2:$D$5001,Maintenance_Log!$B$2:$B$5001,A46)) | V46: =COUNTIFS(Maintenance_Log!$B$2:$B$5001,A46,Maintenance_Log!$H$2:$H$5001,"<>Completed",Maintenance_Log!$H$2:$H$5001,"<>Cancelled") -> 0
A47: SHW-0046 | B47: Sherwood Arboretum | C47: 46 | D47: -27.531598 | E47: 152.97392 | F47: Agathis robusta | G47: Queensland kauri pine | H47: Araucariaceae | I47: 9 | J47: 2 | K47: 180 | L47: 2014 | M47: NALL-CV-2257, NALL-SNV-881, NALL-WWV-2529 | N47: No | O47: =COUNTIF(Health_Assessments!$B$2:$B$5001,A47) -> 0 | P47: =IF(O47=0,"",_xlfn.MAXIFS(Health_Assessments!$C$2:$C$5001,Health_Assessments!$B$2:$B$5001,A47)) | Q47: =IF(O47=0,"",LOOKUP(2,1/((Health_Assessments!$B$2:$B$5001=A47)*(Health_Assessments!$C$2:$C$5001=P47)),Health_Assessments!$E$2:$E$5001)) | R47: =IF(O47=0,"",LOOKUP(2,1/((Health_Assessments!$B$2:$B$5001=A47)*(Health_Assessments!$C$2:$C$5001=P47)),Health_Assessments!$G$2:$G$5001)) | S47: =IF(O47=0,"",LOOKUP(2,1/((Health_Assessments!$B$2:$B$5001=A47)*(Health_Assessments!$C$2:$C$5001=P47)),Health_Assessments!$H$2:$H$5001)) | T47: =COUNTIF(Maintenance_Log!$B$2:$B$5001,A47) -> 0 | U47: =IF(T47=0,"",_xlfn.MAXIFS(Maintenance_Log!$D$2:$D$5001,Maintenance_Log!$B$2:$B$5001,A47)) | V47: =COUNTIFS(Maintenance_Log!$B$2:$B$5001,A47,Maintenance_Log!$H$2:$H$5001,"<>Completed",Maintenance_Log!$H$2:$H$5001,"<>Cancelled") -> 0
A48: SHW-0047 | B48: Sherwood Arboretum | C48: 47 | D48: -27.531707 | E48: 152.97405 | F48: Agathis robusta | G48: Queensland kauri pine | H48: Araucariaceae | I48: 9 | J48: 2 | K48: 170 | L48: 2014 | M48: NALL-CV-2257, NALL-SNV-881, NALL-WWV-2529 | N48: No | O48: =COUNTIF(Health_Assessments!$B$2:$B$5001,A48) -> 0 | P48: =IF(O48=0,"",_xlfn.MAXIFS(Health_Assessments!$C$2:$C$5001,Health_Assessments!$B$2:$B$5001,A48)) | Q48: =IF(O48=0,"",LOOKUP(2,1/((Health_Assessments!$B$2:$B$5001=A48)*(Health_Assessments!$C$2:$C$5001=P48)),Health_Assessments!$E$2:$E$5001)) | R48: =IF(O48=0,"",LOOKUP(2,1/((Health_Assessments!$B$2:$B$5001=A48)*(Health_Assessments!$C$2:$C$5001=P48)),Health_Assessments!$G$2:$G$5001)) | S48: =IF(O48=0,"",LOOKUP(2,1/((Health_Assessments!$B$2:$B$5001=A48)*(Health_Assessments!$C$2:$C$5001=P48)),Health_Assessments!$H$2:$H$5001)) | T48: =COUNTIF(Maintenance_Log!$B$2:$B$5001,A48) -> 0 | U48: =IF(T48=0,"",_xlfn.MAXIFS(Maintenance_Log!$D$2:$D$5001,Maintenance_Log!$B$2:$B$5001,A48)) | V48: =COUNTIFS(Maintenance_Log!$B$2:$B$5001,A48,Maintenance_Log!$H$2:$H$5001,"<>Completed",Maintenance_Log!$H$2:$H$5001,"<>Cancelled") -> 0
A49: SHW-0048 | B49: Sherwood Arboretum | C49: 48 | D49: -27.531716 | E49: 152.97394 | F49: Agathis robusta | G49: Queensland kauri pine | H49: Araucariaceae | I49: 9 | J49: 2 | K49: 180 | L49: 2014 | M49: NALL-CV-2257, NALL-SNV-881, NALL-WWV-2529 | N49: No | O49: =COUNTIF(Health_Assessments!$B$2:$B$5001,A49) -> 0 | P49: =IF(O49=0,"",_xlfn.MAXIFS(Health_Assessments!$C$2:$C$5001,Health_Assessments!$B$2:$B$5001,A49)) | Q49: =IF(O49=0,"",LOOKUP(2,1/((Health_Assessments!$B$2:$B$5001=A49)*(Health_Assessments!$C$2:$C$5001=P49)),Health_Assessments!$E$2:$E$5001)) | R49: =IF(O49=0,"",LOOKUP(2,1/((Health_Assessments!$B$2:$B$5001=A49)*(Health_Assessments!$C$2:$C$5001=P49)),Health_Assessments!$G$2:$G$5001)) | S49: =IF(O49=0,"",LOOKUP(2,1/((Health_Assessments!$B$2:$B$5001=A49)*(Health_Assessments!$C$2:$C$5001=P49)),Health_Assessments!$H$2:$H$5001)) | T49: =COUNTIF(Maintenance_Log!$B$2:$B$5001,A49) -> 0 | U49: =IF(T49=0,"",_xlfn.MAXIFS(Maintenance_Log!$D$2:$D$5001,Maintenance_Log!$B$2:$B$5001,A49)) | V49: =COUNTIFS(Maintenance_Log!$B$2:$B$5001,A49,Maintenance_Log!$H$2:$H$5001,"<>Completed",Maintenance_Log!$H$2:$H$5001,"<>Cancelled") -> 0
A50: SHW-0049 | B50: Sherwood Arboretum | C50: 49 | D50: -27.531809 | E50: 152.97407 | F50: Agathis robusta | G50: Queensland kauri pine | H50: Araucariaceae | I50: 11 | J50: 5 | K50: 350 | M50: NALL-CV-2257, NALL-SNV-881, NALL-WWV-2529 | N50: No | O50: =COUNTIF(Health_Assessments!$B$2:$B$5001,A50) -> 0 | P50: =IF(O50=0,"",_xlfn.MAXIFS(Health_Assessments!$C$2:$C$5001,Health_Assessments!$B$2:$B$5001,A50)) | Q50: =IF(O50=0,"",LOOKUP(2,1/((Health_Assessments!$B$2:$B$5001=A50)*(Health_Assessments!$C$2:$C$5001=P50)),Health_Assessments!$E$2:$E$5001)) | R50: =IF(O50=0,"",LOOKUP(2,1/((Health_Assessments!$B$2:$B$5001=A50)*(Health_Assessments!$C$2:$C$5001=P50)),Health_Assessments!$G$2:$G$5001)) | S50: =IF(O50=0,"",LOOKUP(2,1/((Health_Assessments!$B$2:$B$5001=A50)*(Health_Assessments!$C$2:$C$5001=P50)),Health_Assessments!$H$2:$H$5001)) | T50: =COUNTIF(Maintenance_Log!$B$2:$B$5001,A50) -> 0 | U50: =IF(T50=0,"",_xlfn.MAXIFS(Maintenance_Log!$D$2:$D$5001,Maintenance_Log!$B$2:$B$5001,A50)) | V50: =COUNTIFS(Maintenance_Log!$B$2:$B$5001,A50,Maintenance_Log!$H$2:$H$5001,"<>Completed",Maintenance_Log!$H$2:$H$5001,"<>Cancelled") -> 0
A51: SHW-0050 | B51: Sherwood Arboretum | C51: 50 | D51: -27.531825 | E51: 152.97395 | F51: Agathis robusta | G51: Queensland kauri pine | H51: Araucariaceae | I51: 10 | J51: 3 | K51: 230 | L51: 2012 | M51: NALL-CV-2257, NALL-SNV-881, NALL-WWV-2529 | N51: No | O51: =COUNTIF(Health_Assessments!$B$2:$B$5001,A51) -> 0 | P51: =IF(O51=0,"",_xlfn.MAXIFS(Health_Assessments!$C$2:$C$5001,Health_Assessments!$B$2:$B$5001,A51)) | Q51: =IF(O51=0,"",LOOKUP(2,1/((Health_Assessments!$B$2:$B$5001=A51)*(Health_Assessments!$C$2:$C$5001=P51)),Health_Assessments!$E$2:$E$5001)) | R51: =IF(O51=0,"",LOOKUP(2,1/((Health_Assessments!$B$2:$B$5001=A51)*(Health_Assessments!$C$2:$C$5001=P51)),Health_Assessments!$G$2:$G$5001)) | S51: =IF(O51=0,"",LOOKUP(2,1/((Health_Assessments!$B$2:$B$5001=A51)*(Health_Assessments!$C$2:$C$5001=P51)),Health_Assessments!$H$2:$H$5001)) | T51: =COUNTIF(Maintenance_Log!$B$2:$B$5001,A51) -> 0 | U51: =IF(T51=0,"",_xlfn.MAXIFS(Maintenance_Log!$D$2:$D$5001,Maintenance_Log!$B$2:$B$5001,A51)) | V51: =COUNTIFS(Maintenance_Log!$B$2:$B$5001,A51,Maintenance_Log!$H$2:$H$5001,"<>Completed",Maintenance_Log!$H$2:$H$5001,"<>Cancelled") -> 0
A52: SHW-0051 | B52: Sherwood Arboretum | C52: 51 | D52: -27.531897 | E52: 152.97409 | F52: Agathis robusta | G52: Queensland kauri pine | H52: Araucariaceae | I52: 11 | J52: 3 | K52: 250 | M52: NALL-CV-2257, NALL-SNV-881, NALL-WWV-2529 | N52: No | O52: =COUNTIF(Health_Assessments!$B$2:$B$5001,A52) -> 0 | P52: =IF(O52=0,"",_xlfn.MAXIFS(Health_Assessments!$C$2:$C$5001,Health_Assessments!$B$2:$B$5001,A52)) | Q52: =IF(O52=0,"",LOOKUP(2,1/((Health_Assessments!$B$2:$B$5001=A52)*(Health_Assessments!$C$2:$C$5001=P52)),Health_Assessments!$E$2:$E$5001)) | R52: =IF(O52=0,"",LOOKUP(2,1/((Health_Assessments!$B$2:$B$5001=A52)*(Health_Assessments!$C$2:$C$5001=P52)),Health_Assessments!$G$2:$G$5001)) | S52: =IF(O52=0,"",LOOKUP(2,1/((Health_Assessments!$B$2:$B$5001=A52)*(Health_Assessments!$C$2:$C$5001=P52)),Health_Assessments!$H$2:$H$5001)) | T52: =COUNTIF(Maintenance_Log!$B$2:$B$5001,A52) -> 0 | U52: =IF(T52=0,"",_xlfn.MAXIFS(Maintenance_Log!$D$2:$D$5001,Maintenance_Log!$B$2:$B$5001,A52)) | V52: =COUNTIFS(Maintenance_Log!$B$2:$B$5001,A52,Maintenance_Log!$H$2:$H$5001,"<>Completed",Maintenance_Log!$H$2:$H$5001,"<>Cancelled") -> 0
A53: SHW-0052 | B53: Sherwood Arboretum | C53: 52 | D53: -27.531931 | E53: 152.97397 | F53: Agathis robusta | G53: Queensland kauri pine | H53: Araucariaceae | I53: 18 | J53: 5 | K53: 550 | M53: NALL-CV-2257, NALL-SNV-881 | N53: No | O53: =COUNTIF(Health_Assessments!$B$2:$B$5001,A53) -> 0 | P53: =IF(O53=0,"",_xlfn.MAXIFS(Health_Assessments!$C$2:$C$5001,Health_Assessments!$B$2:$B$5001,A53)) | Q53: =IF(O53=0,"",LOOKUP(2,1/((Health_Assessments!$B$2:$B$5001=A53)*(Health_Assessments!$C$2:$C$5001=P53)),Health_Assessments!$E$2:$E$5001)) | R53: =IF(O53=0,"",LOOKUP(2,1/((Health_Assessments!$B$2:$B$5001=A53)*(Health_Assessments!$C$2:$C$5001=P53)),Health_Assessments!$G$2:$G$5001)) | S53: =IF(O53=0,"",LOOKUP(2,1/((Health_Assessments!$B$2:$B$5001=A53)*(Health_Assessments!$C$2:$C$5001=P53)),Health_Assessments!$H$2:$H$5001)) | T53: =COUNTIF(Maintenance_Log!$B$2:$B$5001,A53) -> 0 | U53: =IF(T53=0,"",_xlfn.MAXIFS(Maintenance_Log!$D$2:$D$5001,Maintenance_Log!$B$2:$B$5001,A53)) | V53: =COUNTIFS(Maintenance_Log!$B$2:$B$5001,A53,Maintenance_Log!$H$2:$H$5001,"<>Completed",Maintenance_Log!$H$2:$H$5001,"<>Cancelled") -> 0
A54: SHW-0053 | B54: Sherwood Arboretum | C54: 53 | D54: -27.532004 | E54: 152.97412 | F54: Agathis robusta | G54: Queensland kauri pine | H54: Araucariaceae | I54: 9 | J54: 3 | K54: 180 | L54: 2012 | M54: NALL-CV-2257, NALL-SNV-881, NALL-WWV-2529 | N54: No | O54: =COUNTIF(Health_Assessments!$B$2:$B$5001,A54) -> 0 | P54: =IF(O54=0,"",_xlfn.MAXIFS(Health_Assessments!$C$2:$C$5001,Health_Assessments!$B$2:$B$5001,A54)) | Q54: =IF(O54=0,"",LOOKUP(2,1/((Health_Assessments!$B$2:$B$5001=A54)*(Health_Assessments!$C$2:$C$5001=P54)),Health_Assessments!$E$2:$E$5001)) | R54: =IF(O54=0,"",LOOKUP(2,1/((Health_Assessments!$B$2:$B$5001=A54)*(Health_Assessments!$C$2:$C$5001=P54)),Health_Assessments!$G$2:$G$5001)) | S54: =IF(O54=0,"",LOOKUP(2,1/((Health_Assessments!$B$2:$B$5001=A54)*(Health_Assessments!$C$2:$C$5001=P54)),Health_Assessments!$H$2:$H$5001)) | T54: =COUNTIF(Maintenance_Log!$B$2:$B$5001,A54) -> 0 | U54: =IF(T54=0,"",_xlfn.MAXIFS(Maintenance_Log!$D$2:$D$5001,Maintenance_Log!$B$2:$B$5001,A54)) | V54: =COUNTIFS(Maintenance_Log!$B$2:$B$5001,A54,Maintenance_Log!$H$2:$H$5001,"<>Completed",Maintenance_Log!$H$2:$H$5001,"<>Cancelled") -> 0
A55: SHW-0054 | B55: Sherwood Arboretum | C55: 54 | D55: -27.532039 | E55: 152.97399 | F55: Agathis robusta | G55: Queensland kauri pine | H55: Araucariaceae | I55: 18 | J55: 11 | K55: 550 | M55: NALL-CV-2257, NALL-SNV-881 | N55: No | O55: =COUNTIF(Health_Assessments!$B$2:$B$5001,A55) -> 0 | P55: =IF(O55=0,"",_xlfn.MAXIFS(Health_Assessments!$C$2:$C$5001,Health_Assessments!$B$2:$B$5001,A55)) | Q55: =IF(O55=0,"",LOOKUP(2,1/((Health_Assessments!$B$2:$B$5001=A55)*(Health_Assessments!$C$2:$C$5001=P55)),Health_Assessments!$E$2:$E$5001)) | R55: =IF(O55=0,"",LOOKUP(2,1/((Health_Assessments!$B$2:$B$5001=A55)*(Health_Assessments!$C$2:$C$5001=P55)),Health_Assessments!$G$2:$G$5001)) | S55: =IF(O55=0,"",LOOKUP(2,1/((Health_Assessments!$B$2:$B$5001=A55)*(Health_Assessments!$C$2:$C$5001=P55)),Health_Assessments!$H$2:$H$5001)) | T55: =COUNTIF(Maintenance_Log!$B$2:$B$5001,A55) -> 0 | U55: =IF(T55=0,"",_xlfn.MAXIFS(Maintenance_Log!$D$2:$D$5001,Maintenance_Log!$B$2:$B$5001,A55)) | V55: =COUNTIFS(Maintenance_Log!$B$2:$B$5001,A55,Maintenance_Log!$H$2:$H$5001,"<>Completed",Maintenance_Log!$H$2:$H$5001,"<>Cancelled") -> 0
A56: SHW-0055 | B56: Sherwood Arboretum | C56: 55 | D56: -27.532122 | E56: 152.97415 | F56: Agathis robusta | G56: Queensland kauri pine | H56: Araucariaceae | I56: 13 | J56: 6 | K56: 330 | M56: NALL-CV-2257, NALL-SNV-881 | N56: No | O56: =COUNTIF(Health_Assessments!$B$2:$B$5001,A56) -> 0 | P56: =IF(O56=0,"",_xlfn.MAXIFS(Health_Assessments!$C$2:$C$5001,Health_Assessments!$B$2:$B$5001,A56)) | Q56: =IF(O56=0,"",LOOKUP(2,1/((Health_Assessments!$B$2:$B$5001=A56)*(Health_Assessments!$C$2:$C$5001=P56)),Health_Assessments!$E$2:$E$5001)) | R56: =IF(O56=0,"",LOOKUP(2,1/((Health_Assessments!$B$2:$B$5001=A56)*(Health_Assessments!$C$2:$C$5001=P56)),Health_Assessments!$G$2:$G$5001)) | S56: =IF(O56=0,"",LOOKUP(2,1/((Health_Assessments!$B$2:$B$5001=A56)*(Health_Assessments!$C$2:$C$5001=P56)),Health_Assessments!$H$2:$H$5001)) | T56: =COUNTIF(Maintenance_Log!$B$2:$B$5001,A56) -> 0 | U56: =IF(T56=0,"",_xlfn.MAXIFS(Maintenance_Log!$D$2:$D$5001,Maintenance_Log!$B$2:$B$5001,A56)) | V56: =COUNTIFS(Maintenance_Log!$B$2:$B$5001,A56,Maintenance_Log!$H$2:$H$5001,"<>Completed",Maintenance_Log!$H$2:$H$5001,"<>Cancelled") -> 0
A57: SHW-0056 | B57: Sherwood Arboretum | C57: 56 | D57: -27.532144 | E57: 152.97402 | F57: Agathis robusta | G57: Queensland kauri pine | H57: Araucariaceae | I57: 14 | J57: 4 | K57: 480 | M57: NALL-CV-2257, NALL-SNV-881 | N57: No | O57: =COUNTIF(Health_Assessments!$B$2:$B$5001,A57) -> 0 | P57: =IF(O57=0,"",_xlfn.MAXIFS(Health_Assessments!$C$2:$C$5001,Health_Assessments!$B$2:$B$5001,A57)) | Q57: =IF(O57=0,"",LOOKUP(2,1/((Health_Assessments!$B$2:$B$5001=A57)*(Health_Assessments!$C$2:$C$5001=P57)),Health_Assessments!$E$2:$E$5001)) | R57: =IF(O57=0,"",LOOKUP(2,1/((Health_Assessments!$B$2:$B$5001=A57)*(Health_Assessments!$C$2:$C$5001=P57)),Health_Assessments!$G$2:$G$5001)) | S57: =IF(O57=0,"",LOOKUP(2,1/((Health_Assessments!$B$2:$B$5001=A57)*(Health_Assessments!$C$2:$C$5001=P57)),Health_Assessments!$H$2:$H$5001)) | T57: =COUNTIF(Maintenance_Log!$B$2:$B$5001,A57) -> 0 | U57: =IF(T57=0,"",_xlfn.MAXIFS(Maintenance_Log!$D$2:$D$5001,Maintenance_Log!$B$2:$B$5001,A57)) | V57: =COUNTIFS(Maintenance_Log!$B$2:$B$5001,A57,Maintenance_Log!$H$2:$H$5001,"<>Completed",Maintenance_Log!$H$2:$H$5001,"<>Cancelled") -> 0
A58: SHW-0057 | B58: Sherwood Arboretum | C58: 57 | D58: -27.532234 | E58: 152.97415 | F58: Agathis robusta | G58: Queensland kauri pine | H58: Araucariaceae | I58: 7 | J58: 2 | K58: 130 | M58: NALL-CV-2257, NALL-SNV-881 | N58: No | O58: =COUNTIF(Health_Assessments!$B$2:$B$5001,A58) -> 0 | P58: =IF(O58=0,"",_xlfn.MAXIFS(Health_Assessments!$C$2:$C$5001,Health_Assessments!$B$2:$B$5001,A58)) | Q58: =IF(O58=0,"",LOOKUP(2,1/((Health_Assessments!$B$2:$B$5001=A58)*(Health_Assessments!$C$2:$C$5001=P58)),Health_Assessments!$E$2:$E$5001)) | R58: =IF(O58=0,"",LOOKUP(2,1/((Health_Assessments!$B$2:$B$5001=A58)*(Health_Assessments!$C$2:$C$5001=P58)),Health_Assessments!$G$2:$G$5001)) | S58: =IF(O58=0,"",LOOKUP(2,1/((Health_Assessments!$B$2:$B$5001=A58)*(Health_Assessments!$C$2:$C$5001=P58)),Health_Assessments!$H$2:$H$5001)) | T58: =COUNTIF(Maintenance_Log!$B$2:$B$5001,A58) -> 0 | U58: =IF(T58=0,"",_xlfn.MAXIFS(Maintenance_Log!$D$2:$D$5001,Maintenance_Log!$B$2:$B$5001,A58)) | V58: =COUNTIFS(Maintenance_Log!$B$2:$B$5001,A58,Maintenance_Log!$H$2:$H$5001,"<>Completed",Maintenance_Log!$H$2:$H$5001,"<>Cancelled") -> 0
A59: SHW-0058 | B59: Sherwood Arboretum | C59: 58 | D59: -27.532259 | E59: 152.97404 | F59: Agathis robusta | G59: Queensland kauri pine | H59: Araucariaceae | I59: 14 | J59: 10 | K59: 441 | M59: NALL-CV-2257, NALL-SNV-881 | N59: No | O59: =COUNTIF(Health_Assessments!$B$2:$B$5001,A59) -> 0 | P59: =IF(O59=0,"",_xlfn.MAXIFS(Health_Assessments!$C$2:$C$5001,Health_Assessments!$B$2:$B$5001,A59)) | Q59: =IF(O59=0,"",LOOKUP(2,1/((Health_Assessments!$B$2:$B$5001=A59)*(Health_Assessments!$C$2:$C$5001=P59)),Health_Assessments!$E$2:$E$5001)) | R59: =IF(O59=0,"",LOOKUP(2,1/((Health_Assessments!$B$2:$B$5001=A59)*(Health_Assessments!$C$2:$C$5001=P59)),Health_Assessments!$G$2:$G$5001)) | S59: =IF(O59=0,"",LOOKUP(2,1/((Health_Assessments!$B$2:$B$5001=A59)*(Health_Assessments!$C$2:$C$5001=P59)),Health_Assessments!$H$2:$H$5001)) | T59: =COUNTIF(Maintenance_Log!$B$2:$B$5001,A59) -> 0 | U59: =IF(T59=0,"",_xlfn.MAXIFS(Maintenance_Log!$D$2:$D$5001,Maintenance_Log!$B$2:$B$5001,A59)) | V59: =COUNTIFS(Maintenance_Log!$B$2:$B$5001,A59,Maintenance_Log!$H$2:$H$5001,"<>Completed",Maintenance_Log!$H$2:$H$5001,"<>Cancelled") -> 0
A60: SHW-0059 | B60: Sherwood Arboretum | C60: 59 | D60: -27.53232 | E60: 152.97418 | F60: Agathis robusta | G60: Queensland kauri pine | H60: Araucariaceae | I60: 12 | J60: 7 | K60: 330 | M60: NALL-CV-2257, NALL-SNV-881 | N60: No | O60: =COUNTIF(Health_Assessments!$B$2:$B$5001,A60) -> 0 | P60: =IF(O60=0,"",_xlfn.MAXIFS(Health_Assessments!$C$2:$C$5001,Health_Assessments!$B$2:$B$5001,A60)) | Q60: =IF(O60=0,"",LOOKUP(2,1/((Health_Assessments!$B$2:$B$5001=A60)*(Health_Assessments!$C$2:$C$5001=P60)),Health_Assessments!$E$2:$E$5001)) | R60: =IF(O60=0,"",LOOKUP(2,1/((Health_Assessments!$B$2:$B$5001=A60)*(Health_Assessments!$C$2:$C$5001=P60)),Health_Assessments!$G$2:$G$5001)) | S60: =IF(O60=0,"",LOOKUP(2,1/((Health_Assessments!$B$2:$B$5001=A60)*(Health_Assessments!$C$2:$C$5001=P60)),Health_Assessments!$H$2:$H$5001)) | T60: =COUNTIF(Maintenance_Log!$B$2:$B$5001,A60) -> 0 | U60: =IF(T60=0,"",_xlfn.MAXIFS(Maintenance_Log!$D$2:$D$5001,Maintenance_Log!$B$2:$B$5001,A60)) | V60: =COUNTIFS(Maintenance_Log!$B$2:$B$5001,A60,Maintenance_Log!$H$2:$H$5001,"<>Completed",Maintenance_Log!$H$2:$H$5001,"<>Cancelled") -> 0
A61: SHW-0060 | B61: Sherwood Arboretum | C61: 60 | D61: -27.532365 | E61: 152.97406 | F61: Agathis robusta | G61: Queensland kauri pine | H61: Araucariaceae | I61: 14 | J61: 8 | K61: 440 | M61: NALL-CV-2257, NALL-SNV-881 | N61: No | O61: =COUNTIF(Health_Assessments!$B$2:$B$5001,A61) -> 0 | P61: =IF(O61=0,"",_xlfn.MAXIFS(Health_Assessments!$C$2:$C$5001,Health_Assessments!$B$2:$B$5001,A61)) | Q61: =IF(O61=0,"",LOOKUP(2,1/((Health_Assessments!$B$2:$B$5001=A61)*(Health_Assessments!$C$2:$C$5001=P61)),Health_Assessments!$E$2:$E$5001)) | R61: =IF(O61=0,"",LOOKUP(2,1/((Health_Assessments!$B$2:$B$5001=A61)*(Health_Assessments!$C$2:$C$5001=P61)),Health_Assessments!$G$2:$G$5001)) | S61: =IF(O61=0,"",LOOKUP(2,1/((Health_Assessments!$B$2:$B$5001=A61)*(Health_Assessments!$C$2:$C$5001=P61)),Health_Assessments!$H$2:$H$5001)) | T61: =COUNTIF(Maintenance_Log!$B$2:$B$5001,A61) -> 0 | U61: =IF(T61=0,"",_xlfn.MAXIFS(Maintenance_Log!$D$2:$D$5001,Maintenance_Log!$B$2:$B$5001,A61)) | V61: =COUNTIFS(Maintenance_Log!$B$2:$B$5001,A61,Maintenance_Log!$H$2:$H$5001,"<>Completed",Maintenance_Log!$H$2:$H$5001,"<>Cancelled") -> 0
A62: SHW-0061 | B62: Sherwood Arboretum | C62: 61 | D62: -27.532447 | E62: 152.97419 | F62: Agathis robusta | G62: Queensland kauri pine | H62: Araucariaceae | I62: 16 | J62: 8 | K62: 460 | M62: NALL-CV-2257, NALL-SNV-881 | N62: No | O62: =COUNTIF(Health_Assessments!$B$2:$B$5001,A62) -> 0 | P62: =IF(O62=0,"",_xlfn.MAXIFS(Health_Assessments!$C$2:$C$5001,Health_Assessments!$B$2:$B$5001,A62)) | Q62: =IF(O62=0,"",LOOKUP(2,1/((Health_Assessments!$B$2:$B$5001=A62)*(Health_Assessments!$C$2:$C$5001=P62)),Health_Assessments!$E$2:$E$5001)) | R62: =IF(O62=0,"",LOOKUP(2,1/((Health_Assessments!$B$2:$B$5001=A62)*(Health_Assessments!$C$2:$C$5001=P62)),Health_Assessments!$G$2:$G$5001)) | S62: =IF(O62=0,"",LOOKUP(2,1/((Health_Assessments!$B$2:$B$5001=A62)*(Health_Assessments!$C$2:$C$5001=P62)),Health_Assessments!$H$2:$H$5001)) | T62: =COUNTIF(Maintenance_Log!$B$2:$B$5001,A62) -> 0 | U62: =IF(T62=0,"",_xlfn.MAXIFS(Maintenance_Log!$D$2:$D$5001,Maintenance_Log!$B$2:$B$5001,A62)) | V62: =COUNTIFS(Maintenance_Log!$B$2:$B$5001,A62,Maintenance_Log!$H$2:$H$5001,"<>Completed",Maintenance_Log!$H$2:$H$5001,"<>Cancelled") -> 0
A63: SHW-0062 | B63: Sherwood Arboretum | C63: 62 | D63: -27.532475 | E63: 152.97407 | F63: Agathis robusta | G63: Queensland kauri pine | H63: Araucariaceae | I63: 16 | J63: 6 | K63: 440 | M63: NALL-CV-2257, NALL-SNV-881 | N63: No | O63: =COUNTIF(Health_Assessments!$B$2:$B$5001,A63) -> 0 | P63: =IF(O63=0,"",_xlfn.MAXIFS(Health_Assessments!$C$2:$C$5001,Health_Assessments!$B$2:$B$5001,A63)) | Q63: =IF(O63=0,"",LOOKUP(2,1/((Health_Assessments!$B$2:$B$5001=A63)*(Health_Assessments!$C$2:$C$5001=P63)),Health_Assessments!$E$2:$E$5001)) | R63: =IF(O63=0,"",LOOKUP(2,1/((Health_Assessments!$B$2:$B$5001=A63)*(Health_Assessments!$C$2:$C$5001=P63)),Health_Assessments!$G$2:$G$5001)) | S63: =IF(O63=0,"",LOOKUP(2,1/((Health_Assessments!$B$2:$B$5001=A63)*(Health_Assessments!$C$2:$C$5001=P63)),Health_Assessments!$H$2:$H$5001)) | T63: =COUNTIF(Maintenance_Log!$B$2:$B$5001,A63) -> 0 | U63: =IF(T63=0,"",_xlfn.MAXIFS(Maintenance_Log!$D$2:$D$5001,Maintenance_Log!$B$2:$B$5001,A63)) | V63: =COUNTIFS(Maintenance_Log!$B$2:$B$5001,A63,Maintenance_Log!$H$2:$H$5001,"<>Completed",Maintenance_Log!$H$2:$H$5001,"<>Cancelled") -> 0
A64: SHW-0063 | B64: Sherwood Arboretum | C64: 63 | D64: -27.53255 | E64: 152.97421 | F64: Agathis robusta | G64: Queensland kauri pine | H64: Araucariaceae | I64: 18 | J64: 11 | K64: 530 | M64: NALL-CV-2257, NALL-SNV-881 | N64: No | O64: =COUNTIF(Health_Assessments!$B$2:$B$5001,A64) -> 0 | P64: =IF(O64=0,"",_xlfn.MAXIFS(Health_Assessments!$C$2:$C$5001,Health_Assessments!$B$2:$B$5001,A64)) | Q64: =IF(O64=0,"",LOOKUP(2,1/((Health_Assessments!$B$2:$B$5001=A64)*(Health_Assessments!$C$2:$C$5001=P64)),Health_Assessments!$E$2:$E$5001)) | R64: =IF(O64=0,"",LOOKUP(2,1/((Health_Assessments!$B$2:$B$5001=A64)*(Health_Assessments!$C$2:$C$5001=P64)),Health_Assessments!$G$2:$G$5001)) | S64: =IF(O64=0,"",LOOKUP(2,1/((Health_Assessments!$B$2:$B$5001=A64)*(Health_Assessments!$C$2:$C$5001=P64)),Health_Assessments!$H$2:$H$5001)) | T64: =COUNTIF(Maintenance_Log!$B$2:$B$5001,A64) -> 0 | U64: =IF(T64=0,"",_xlfn.MAXIFS(Maintenance_Log!$D$2:$D$5001,Maintenance_Log!$B$2:$B$5001,A64)) | V64: =COUNTIFS(Maintenance_Log!$B$2:$B$5001,A64,Maintenance_Log!$H$2:$H$5001,"<>Completed",Maintenance_Log!$H$2:$H$5001,"<>Cancelled") -> 0
A65: SHW-0064 | B65: Sherwood Arboretum | C65: 64 | D65: -27.53258 | E65: 152.97409 | F65: Agathis robusta | G65: Queensland kauri pine | H65: Araucariaceae | I65: 17 | J65: 8 | K65: 440 | M65: NALL-CV-2257, NALL-SNV-881 | N65: No | O65: =COUNTIF(Health_Assessments!$B$2:$B$5001,A65) -> 0 | P65: =IF(O65=0,"",_xlfn.MAXIFS(Health_Assessments!$C$2:$C$5001,Health_Assessments!$B$2:$B$5001,A65)) | Q65: =IF(O65=0,"",LOOKUP(2,1/((Health_Assessments!$B$2:$B$5001=A65)*(Health_Assessments!$C$2:$C$5001=P65)),Health_Assessments!$E$2:$E$5001)) | R65: =IF(O65=0,"",LOOKUP(2,1/((Health_Assessments!$B$2:$B$5001=A65)*(Health_Assessments!$C$2:$C$5001=P65)),Health_Assessments!$G$2:$G$5001)) | S65: =IF(O65=0,"",LOOKUP(2,1/((Health_Assessments!$B$2:$B$5001=A65)*(Health_Assessments!$C$2:$C$5001=P65)),Health_Assessments!$H$2:$H$5001)) | T65: =COUNTIF(Maintenance_Log!$B$2:$B$5001,A65) -> 0 | U65: =IF(T65=0,"",_xlfn.MAXIFS(Maintenance_Log!$D$2:$D$5001,Maintenance_Log!$B$2:$B$5001,A65)) | V65: =COUNTIFS(Maintenance_Log!$B$2:$B$5001,A65,Maintenance_Log!$H$2:$H$5001,"<>Completed",Maintenance_Log!$H$2:$H$5001,"<>Cancelled") -> 0
A66: SHW-0065 | B66: Sherwood Arboretum | C66: 65 | D66: -27.532658 | E66: 152.97424 | F66: Agathis robusta | G66: Queensland kauri pine | H66: Araucariaceae | I66: 15 | J66: 9 | K66: 410 | M66: NALL-CV-2257, NALL-SNV-881 | N66: No | O66: =COUNTIF(Health_Assessments!$B$2:$B$5001,A66) -> 0 | P66: =IF(O66=0,"",_xlfn.MAXIFS(Health_Assessments!$C$2:$C$5001,Health_Assessments!$B$2:$B$5001,A66)) | Q66: =IF(O66=0,"",LOOKUP(2,1/((Health_Assessments!$B$2:$B$5001=A66)*(Health_Assessments!$C$2:$C$5001=P66)),Health_Assessments!$E$2:$E$5001)) | R66: =IF(O66=0,"",LOOKUP(2,1/((Health_Assessments!$B$2:$B$5001=A66)*(Health_Assessments!$C$2:$C$5001=P66)),Health_Assessments!$G$2:$G$5001)) | S66: =IF(O66=0,"",LOOKUP(2,1/((Health_Assessments!$B$2:$B$5001=A66)*(Health_Assessments!$C$2:$C$5001=P66)),Health_Assessments!$H$2:$H$5001)) | T66: =COUNTIF(Maintenance_Log!$B$2:$B$5001,A66) -> 0 | U66: =IF(T66=0,"",_xlfn.MAXIFS(Maintenance_Log!$D$2:$D$5001,Maintenance_Log!$B$2:$B$5001,A66)) | V66: =COUNTIFS(Maintenance_Log!$B$2:$B$5001,A66,Maintenance_Log!$H$2:$H$5001,"<>Completed",Maintenance_Log!$H$2:$H$5001,"<>Cancelled") -> 0
... A73: SHW-0072 | B73: Sherwood Arboretum | C73: 72 | D73: -27.533014 | E73: 152.97417 | F73: Agathis robusta | G73: Queensland kauri pine | H73: Araucariaceae | I73: 17 | J73: 12 | K73: 380 | M73: NALL-CV-2257, NALL-SNV-881 | N73: No | O73: =COUNTIF(Health_Assessments!$B$2:$B$5001,A73) -> 0 | P73: =IF(O73=0,"",_xlfn.MAXIFS(Health_Assessments!$C$2:$C$5001,Health_Assessments!$B$2:$B$5001,A73)) | Q73: =IF(O73=0,"",LOOKUP(2,1/((Health_Assessments!$B$2:$B$5001=A73)*(Health_Assessments!$C$2:$C$5001=P73)),Health_Assessments!$E$2:$E$5001)) | R73: =IF(O73=0,"",LOOKUP(2,1/((Health_Assessments!$B$2:$B$5001=A73)*(Health_Assessments!$C$2:$C$5001=P73)),Health_Assessments!$G$2:$G$5001)) | S73: =IF(O73=0,"",LOOKUP(2,1/((Health_Assessments!$B$2:$B$5001=A73)*(Health_Assessments!$C$2:$C$5001=P73)),Health_Assessments!$H$2:$H$5001)) | T73: =COUNTIF(Maintenance_Log!$B$2:$B$5001,A73) -> 0 | U73: =IF(T73=0,"",_xlfn.MAXIFS(Maintenance_Log!$D$2:$D$5001,Maintenance_Log!$B$2:$B$5001,A73)) | V73: =COUNTIFS(Maintenance_Log!$B$2:$B$5001,A73,Maintenance_Log!$H$2:$H$5001,"<>Completed",Maintenance_Log!$H$2:$H$5001,"<>Cancelled") -> 0
...

Sheet Health_Assessments
A1: Assessment_ID | B1: Tree_ID | C1: Assessment_Date | D1: Assessor | E1: Condition | F1: Issue_Type | G1: Risk_Rating | H1: Recommended_Outcome | I1: Council_Request_Ref | J1: Notes
A2: HA-0001 | B2: SHW-0661 | C2: 46323 | D2: EXAMPLE – replace or delete this row | E2: Fair | F2: Fallen or broken branches | G2: Medium | H2: Pruning | J2: Example: broken limb over path, crown otherwise healthy.

Sheet Maintenance_Log
A1: Work_ID | B1: Tree_ID | C1: Assessment_ID | D1: Work_Date | E1: Work_Type | F1: Clearance_Context | G1: Required_Clearance_m | H1: Status | I1: Crew_or_Contractor | J1: Council_Request_Ref | K1: Notes
A2: WK-0001 | B2: SHW-0661 | C2: HA-0001 | D2: 46323 | E2: Clearance pruning | F2: Verge or footpath | G2: =IF(F2="","",IFERROR(INDEX(Lookups!$G$2:$G$6,MATCH(F2,Lookups!$F$2:$F$6,0)),"")) -> 2.4 | H2: Scheduled | K2: EXAMPLE – replace or delete this row
G3: =IF(F3="","",IFERROR(INDEX(Lookups!$G$2:$G$6,MATCH(F3,Lookups!$F$2:$F$6,0)),""))
G4: =IF(F4="","",IFERROR(INDEX(Lookups!$G$2:$G$6,MATCH(F4,Lookups!$F$2:$F$6,0)),""))
G5: =IF(F5="","",IFERROR(INDEX(Lookups!$G$2:$G$6,MATCH(F5,Lookups!$F$2:$F$6,0)),""))
G6: =IF(F6="","",IFERROR(INDEX(Lookups!$G$2:$G$6,MATCH(F6,Lookups!$F$2:$F$6,0)),""))
G7: =IF(F7="","",IFERROR(INDEX(Lookups!$G$2:$G$6,MATCH(F7,Lookups!$F$2:$F$6,0)),""))
G8: =IF(F8="","",IFERROR(INDEX(Lookups!$G$2:$G$6,MATCH(F8,Lookups!$F$2:$F$6,0)),""))
G9: =IF(F9="","",IFERROR(INDEX(Lookups!$G$2:$G$6,MATCH(F9,Lookups!$F$2:$F$6,0)),""))
G10: =IF(F10="","",IFERROR(INDEX(Lookups!$G$2:$G$6,MATCH(F10,Lookups!$F$2:$F$6,0)),""))
G11: =IF(F11="","",IFERROR(INDEX(Lookups!$G$2:$G$6,MATCH(F11,Lookups!$F$2:$F$6,0)),""))
G12: =IF(F12="","",IFERROR(INDEX(Lookups!$G$2:$G$6,MATCH(F12,Lookups!$F$2:$F$6,0)),""))
G13: =IF(F13="","",IFERROR(INDEX(Lookups!$G$2:$G$6,MATCH(F13,Lookups!$F$2:$F$6,0)),""))
G14: =IF(F14="","",IFERROR(INDEX(Lookups!$G$2:$G$6,MATCH(F14,Lookups!$F$2:$F$6,0)),""))
... G5001: =IF(F5001="","",IFERROR(INDEX(Lookups!$G$2:$G$6,MATCH(F5001,Lookups!$F$2:$F$6,0)),""))

Sheet Protected_Areas
A1: Area_ID | B1: Layer | C1: Category | D1: Description | E1: Centroid_Latitude | F1: Centroid_Longitude | G1: Area_m2
A2: NALL-CV-1 | B2: Council Vegetation | C2: Council Vegetation | E2: -27.580837 | F2: 152.98276 | G2: 59.686035
A3: NALL-CV-2 | B3: Council Vegetation | C3: Council Vegetation | E3: -27.537139 | F3: 152.89172 | G3: 9091.6516
A4: NALL-CV-3 | B4: Council Vegetation | C4: Council Vegetation | E4: -27.571505 | F4: 152.98405 | G4: 34.599609
A5: NALL-CV-4 | B5: Council Vegetation | C5: Council Vegetation | E5: -27.498647 | F5: 153.09158 | G5: 13185.45
A6: NALL-CV-5 | B6: Council Vegetation | C6: Council Vegetation | E6: -27.623308 | F6: 153.05455 | G6: 15073.881
A7: NALL-CV-6 | B7: Council Vegetation | C7: Council Vegetation | E7: -27.558592 | F7: 153.08412 | G7: 18.307373
A8: NALL-CV-7 | B8: Council Vegetation | C8: Council Vegetation | E8: -27.547574 | F8: 152.97361 | G8: 1214.0449
A9: NALL-CV-8 | B9: Council Vegetation | C9: Council Vegetation | E9: -27.409168 | F9: 152.97279 | G9: 1207.5212
A10: NALL-CV-9 | B10: Council Vegetation | C10: Council Vegetation | E10: -27.562317 | F10: 152.97965 | G10: 2670.0796
A11: NALL-CV-10 | B11: Council Vegetation | C11: Council Vegetation | E11: -27.635439 | F11: 152.9834 | G11: 9992.5105
A12: NALL-CV-11 | B12: Council Vegetation | C12: Council Vegetation | E12: -27.598894 | F12: 153.05193 | G12: 28.505371
A13: NALL-CV-12 | B13: Council Vegetation | C13: Council Vegetation | E13: -27.503166 | F13: 152.93452 | G13: 19676.244
... A15624: CP-SLT-1740 | B15624: City Plan 2014 Significant landscape tree overlay | C15624: Significant landscape tree – vegetation protection order sub-category | E15624: -27.513436 | F15624: 152.9701 | G15624: 568.34863

Sheet Lookups
A1: Condition | B1: Issue_Type | C1: Risk_Rating | D1: Recommended_Outcome | E1: Work_Type | F1: Clearance_Context | G1: Min_Clearance_m | H1: Status
A2: Good | B2: None observed | C2: Low | D2: No action | E2: Structural pruning (young tree) | F2: Verge or footpath | G2: 2.4 | H2: Requested
A3: Fair | B3: Damaged or split | C3: Medium | D3: Pruning | E3: Clearance pruning | F3: Residential or industrial road | G3: 4.5 | H3: Scheduled
A4: Poor | B4: Leaning | C4: High | D4: Health management (tree rehabilitation) | E4: Dead or diseased wood removal | F4: Bikeway | G4: 4.5 | H4: In progress
A5: Dead | B5: Dead or dying | C5: Extreme | D5: Removal and replacement planting | E5: Pest and disease management | F5: Arterial road | G5: 5 | H5: Completed
A6: Unknown | B6: Diseased or unhealthy | E6: Storm damage clean-up | F6: Not applicable | H6: Cancelled
B7: Pests | E7: Health management (rehabilitation)
B8: Fallen or broken branches | E8: Removal
B9: Obstructing footpath, road or sign | E9: Stump grinding
B10: Imminent risk | E10: Replacement planting
B11: Storm damage | E11: Inspection only
B12: Other

Sheet Sources
A1: Dataset | B1: Used for | C1: Records | D1: URL
A2: Botanic collection — Sherwood Arboretum | B2: Tree_Register (individual trees with location) | C2: 1181 | D2: https://services2.arcgis.com/dEKgZETqwmDAh1rP/arcgis/rest/services/botanic_collection_sherwood_arboretum/FeatureServer/0
A3: Protected Vegetation (NALL 2003) — Council Vegetation | B3: Protected_Areas; register column M | C3: 5049 | D3: https://services2.arcgis.com/dEKgZETqwmDAh1rP/arcgis/rest/services/Protected_Vegetation_Natural_Assets_Local_Law_2003_Council_Vegetation/FeatureServer/0
A4: Protected Vegetation (NALL 2003) — Significant Urban Vegetation | B4: Protected_Areas; register column M | C4: 4192 | D4: https://services2.arcgis.com/dEKgZETqwmDAh1rP/arcgis/rest/services/Protected_Vegetation_Natural_Assets_Local_Law_2003_Significant_Urban_Vegetation/FeatureServer/0
A5: Protected Vegetation (NALL 2003) — Significant Native Vegetation | B5: Protected_Areas; register column M | C5: 2056 | D5: https://services2.arcgis.com/dEKgZETqwmDAh1rP/arcgis/rest/services/Protected_Vegetation_Natural_Assets_Local_Law_2003_Significant_Native_Vegetation/FeatureServer/0
A6: Protected Vegetation (NALL 2003) — Waterway and Wetland Vegetation | B6: Protected_Areas; register column M | C6: 2586 | D6: https://services2.arcgis.com/dEKgZETqwmDAh1rP/arcgis/rest/services/Protected_Vegetation_Natural_Assets_Local_Law_2003_Waterway_and_Wetland_Vegetation/FeatureServer/0
A7: City Plan 2014 Significant landscape tree overlay | B7: Protected_Areas; register column N | C7: 1740 | D7: https://services2.arcgis.com/dEKgZETqwmDAh1rP/arcgis/rest/services/Significant_landscape_tree_overlay/FeatureServer/0
A8: Brisbane trees (Council web page) | B8: Lookups: outcomes, clearances, request reasons | D8: https://www.brisbane.qld.gov.au/environment-and-water/plants--trees-and-gardening/brisbane-trees
A9: Request tree removal assessment (Council web page) | B9: Lookups: removal reasons | D9: https://www.brisbane.qld.gov.au/online-services/report-an-issue/report-it-tree-removal
